Workbook
Name Slicer_Department: #N/A
Name Slicer_Gender: #N/A
Name Slicer_Performance: #N/A

Sheet HR analytics dashboard
A1: EmpID | B1: Name | C1: Department | D1: Gender | E1: Age | F1: Salary | G1: Experience | H1: Performance | I1: Attrition | J1: countif | K1: count employess | L1: attrition rate%
A2: 1 | B2: Amit | C2: Sales | D2: Male | E2: 28 | F2: 40000 | G2: 3 | H2: Good | I2: No | J2: =COUNTIF('HR analytics dashboard'!$I$2:$I$13,"Yes") -> 4 | K2: =COUNTA('HR analytics dashboard'!$A$2:$A$13) -> 12 | L2: ='HR analytics dashboard'!$J2/'HR analytics dashboard'!$K2 -> 0.33333333
A3: 2 | B3: Neha | C3: HR | D3: Female | E3: 32 | F3: 45000 | G3: 5 | H3: Excellent | I3: No | J3: =COUNTIF('HR analytics dashboard'!$I$2:$I$13,"Yes") -> 4 | K3: =COUNTA('HR analytics dashboard'!$A$2:$A$13) -> 12 | L3: ='HR analytics dashboard'!$J3/'HR analytics dashboard'!$K3 -> 0.33333333
A4: 3 | B4: Ravi | C4: IT | D4: Male | E4: 26 | F4: 38000 | G4: 2 | H4: Average | I4: Yes | J4: =COUNTIF('HR analytics dashboard'!$I$2:$I$13,"Yes") -> 4 | K4: =COUNTA('HR analytics dashboard'!$A$2:$A$13) -> 12 | L4: ='HR analytics dashboard'!$J4/'HR analytics dashboard'!$K4 -> 0.33333333
A5: 4 | B5: Pooja | C5: Finance | D5: Female | E5: 35 | F5: 50000 | G5: 7 | H5: Good | I5: No | J5: =COUNTIF('HR analytics dashboard'!$I$2:$I$13,"Yes") -> 4 | K5: =COUNTA('HR analytics dashboard'!$A$2:$A$13) -> 12 | L5: ='HR analytics dashboard'!$J5/'HR analytics dashboard'!$K5 -> 0.33333333
A6: 5 | B6: Karan | C6: IT | D6: Male | E6: 29 | F6: 42000 | G6: 4 | H6: Excellent | I6: No | J6: =COUNTIF('HR analytics dashboard'!$I$2:$I$13,"Yes") -> 4 | K6: =COUNTA('HR analytics dashboard'!$A$2:$A$13) -> 12 | L6: ='HR analytics dashboard'!$J6/'HR analytics dashboard'!$K6 -> 0.33333333
A7: 6 | B7: Anita | C7: Sales | D7: Female | E7: 31 | F7: 41000 | G7: 6 | H7: Average | I7: Yes | J7: =COUNTIF('HR analytics dashboard'!$I$2:$I$13,"Yes") -> 4 | K7: =COUNTA('HR analytics dashboard'!$A$2:$A$13) -> 12 | L7: ='HR analytics dashboard'!$J7/'HR analytics dashboard'!$K7 -> 0.33333333
A8: 7 | B8: Rohit | C8: Finance | D8: Male | E8: 34 | F8: 48000 | G8: 8 | H8: Good | I8: No | J8: =COUNTIF('HR analytics dashboard'!$I$2:$I$13,"Yes") -> 4 | K8: =COUNTA('HR analytics dashboard'!$A$2:$A$13) -> 12 | L8: ='HR analytics dashboard'!$J8/'HR analytics dashboard'!$K8 -> 0.33333333
A9: 8 | B9: Sneha | C9: HR | D9: Female | E9: 27 | F9: 39000 | G9: 2 | H9: Good | I9: Yes | J9: =COUNTIF('HR analytics dashboard'!$I$2:$I$13,"Yes") -> 4 | K9: =COUNTA('HR analytics dashboard'!$A$2:$A$13) -> 12 | L9: ='HR analytics dashboard'!$J9/'HR analytics dashboard'!$K9 -> 0.33333333
A10: 9 | B10: Arjun | C10: IT | D10: Male | E10: 30 | F10: 46000 | G10: 5 | H10: Excellent | I10: No | J10: =COUNTIF('HR analytics dashboard'!$I$2:$I$13,"Yes") -> 4 | K10: =COUNTA('HR analytics dashboard'!$A$2:$A$13) -> 12 | L10: ='HR analytics dashboard'!$J10/'HR analytics dashboard'!$K10 -> 0.33333333
A11: 10 | B11: Kavya | C11: Sales | D11: Female | E11: 33 | F11: 47000 | G11: 6 | H11: Good | I11: No | J11: =COUNTIF('HR analytics dashboard'!$I$2:$I$13,"Yes") -> 4 | K11: =COUNTA('HR analytics dashboard'!$A$2:$A$13) -> 12 | L11: ='HR analytics dashboard'!$J11/'HR analytics dashboard'!$K11 -> 0.33333333
A12: 11 | B12: Vikas | C12: Finance | D12: Male | E12: 36 | F12: 52000 | G12: 9 | H12: Excellent | I12: No | J12: =COUNTIF('HR analytics dashboard'!$I$2:$I$13,"Yes") -> 4 | K12: =COUNTA('HR analytics dashboard'!$A$2:$A$13) -> 12 | L12: ='HR analytics dashboard'!$J12/'HR analytics dashboard'!$K12 -> 0.33333333
A13: 12 | B13: Meera | C13: HR | D13: Female | E13: 28 | F13: 40000 | G13: 3 | H13: Average | I13: Yes | J13: =COUNTIF('HR analytics dashboard'!$I$2:$I$13,"Yes") -> 4 | K13: =COUNTA('HR analytics dashboard'!$A$2:$A$13) -> 12 | L13: ='HR analytics dashboard'!$J13/'HR analytics dashboard'!$K13 -> 0.33333333
A16: Count of Name | C16: Average of Salary | E16: Average of countif | G16: Average of attrition rate%
A17: 12 | C17: 44000 | E17: 4 | G17: 0.33333333
A19: =GETPIVOTDATA("Name",$A$16) -> 12 | C19: =GETPIVOTDATA("Salary",$C$16) -> 44000 | E19: =GETPIVOTDATA("countif",$E$16) -> 4 | G19: =GETPIVOTDATA("attrition rate%",$G$16) -> 0.33333333
G21: Attrition | H21: Yes
A22: Row Labels | B22: Count of Name | G22: Attribution by department
A23: Finance | B23: 3 | G23: Row Labels | H23: Count of Attrition
A24: HR | B24: 3 | G24: HR | H24: 2
A25: IT | B25: 3 | G25: IT | H25: 1
A26: Sales | B26: 3 | G26: Sales | H26: 1
A27: Grand Total | B27: 12 | G27: Grand Total | H27: 4 | L27: Average Salary by department
L29: Row Labels | M29: Average of Salary
D30: Attrition | E30: Yes | G30: Row Labels | H30: Count of Gender | L30: Finance | M30: 50000
D31: attrition by department | G31: Female | H31: 6 | L31: HR | M31: 41333.333
A32: performance distribution | D32: Row Labels | E32: Count of Attrition | G32: Male | H32: 6 | L32: IT | M32: 42000
A33: Row Labels | B33: Count of Performance | D33: HR | E33: 2 | G33: Grand Total | H33: 12 | L33: Sales | M33: 42666.667
A34: Average | B34: 3 | D34: IT | E34: 1 | L34: Grand Total | M34: 44000
A35: Excellent | B35: 4 | D35: Sales | E35: 1
A36: Good | B36: 5 | D36: Grand Total | E36: 4
A37: Grand Total | B37: 12
D39: Attrition by performance
D40: Count of EmpID | E40: Column Labels
D41: Row Labels | E41: No | F41: Yes | G41: Grand Total
D42: Average | F42: 3 | G42: 3
D43: Excellent | E43: 4 | G43: 4
D44: Good | E44: 4 | F44: 1 | G44: 5
D45: Grand Total | E45: 8 | F45: 4 | G45: 12
A48: Row Labels | C48: Row Labels | E48: Row Labels
...

Sheet Sheet1
